Workbook

Sheet Equipe
A1: Code | B1: Nom complet de l'équipe | C1: Points marqués par l'équipe en moyenne par match | D1: Nombre de joueurs par équipe
A2: ATL | B2: Atlanta Hawks | C2: =SUMIF('Données NBA'!$B$2:$B$570,Equipe!A2,'Données NBA'!$C$2:$C$570) -> 9689 | D2: =COUNTIF('Données NBA'!$B$2:$B$570,Equipe!A2) -> 18
A3: BKN | B3: Brooklyn Nets | C3: =SUMIF('Données NBA'!$B$2:$B$570,Equipe!A3,'Données NBA'!$C$2:$C$570) -> 7999 | D3: =COUNTIF('Données NBA'!$B$2:$B$570,Equipe!A3) -> 20
A4: BOS | B4: Boston Celtics | C4: =SUMIF('Données NBA'!$B$2:$B$570,Equipe!A4,'Données NBA'!$C$2:$C$570) -> 9551 | D4: =COUNTIF('Données NBA'!$B$2:$B$570,Equipe!A4) -> 17
A5: CHA | B5: Charlotte Hornets | C5: =SUMIF('Données NBA'!$B$2:$B$570,Equipe!A5,'Données NBA'!$C$2:$C$570) -> 8278 | D5: =COUNTIF('Données NBA'!$B$2:$B$570,Equipe!A5) -> 22
A6: CHI | B6: Chicago Bulls | C6: =SUMIF('Données NBA'!$B$2:$B$570,Equipe!A6,'Données NBA'!$C$2:$C$570) -> 9230 | D6: =COUNTIF('Données NBA'!$B$2:$B$570,Equipe!A6) -> 20
A7: CLE | B7: Cleveland Cavaliers | C7: =SUMIF('Données NBA'!$B$2:$B$570,Equipe!A7,'Données NBA'!$C$2:$C$570) -> 10180 | D7: =COUNTIF('Données NBA'!$B$2:$B$570,Equipe!A7) -> 18
A8: DAL | B8: Dallas Mavericks | C8: =SUMIF('Données NBA'!$B$2:$B$570,Equipe!A8,'Données NBA'!$C$2:$C$570) -> 9970 | D8: =COUNTIF('Données NBA'!$B$2:$B$570,Equipe!A8) -> 19
A9: DEN | B9: Denver Nuggets | C9: =SUMIF('Données NBA'!$B$2:$B$570,Equipe!A9,'Données NBA'!$C$2:$C$570) -> 9899 | D9: =COUNTIF('Données NBA'!$B$2:$B$570,Equipe!A9) -> 17
A10: DET | B10: Detroit Pistons | C10: =SUMIF('Données NBA'!$B$2:$B$570,Equipe!A10,'Données NBA'!$C$2:$C$570) -> 10292 | D10: =COUNTIF('Données NBA'!$B$2:$B$570,Equipe!A10) -> 19
A11: GSW | B11: Golden State Warriors | C11: =SUMIF('Données NBA'!$B$2:$B$570,Equipe!A11,'Données NBA'!$C$2:$C$570) -> 8288 | D11: =COUNTIF('Données NBA'!$B$2:$B$570,Equipe!A11) -> 17
A12: HOU | B12: Houston Rockets | C12: =SUMIF('Données NBA'!$B$2:$B$570,Equipe!A12,'Données NBA'!$C$2:$C$570) -> 9515 | D12: =COUNTIF('Données NBA'!$B$2:$B$570,Equipe!A12) -> 18
A13: IND | B13: Indiana Pacers | C13: =SUMIF('Données NBA'!$B$2:$B$570,Equipe!A13,'Données NBA'!$C$2:$C$570) -> 9630 | D13: =COUNTIF('Données NBA'!$B$2:$B$570,Equipe!A13) -> 20
... A31: WAS | B31: Washington Wizards | C31: =SUMIF('Données NBA'!$B$2:$B$570,Equipe!A31,'Données NBA'!$C$2:$C$570) -> 7986 | D31: =COUNTIF('Données NBA'!$B$2:$B$570,Equipe!A31) -> 19

Sheet TCD
A1: Étiquettes de lignes | B1: Somme de OREB | C1: Somme de DREB | D1: Somme de PIE | E1: Somme de AST | F1: Somme de STL | G1: Somme de BLK
A2: ATL | B2: 1011 | C2: 2767 | D2: 171.1 | E2: 2565 | F2: 818 | G2: 442
A3: Caris LeVert | B3: 38 | C3: 160 | D3: 9.4 | E3: 218 | F3: 58 | G3: 32
A4: Clint Capela | B4: 176 | C4: 297 | D4: 11.7 | E4: 61 | F4: 33 | G4: 55
A5: Daeqwon Plowden | B5: 4 | C5: 7 | D5: 12.2 | E5: 2 | F5: 0 | G5: 0
A6: Dominick Barlow | B6: 35 | C6: 49 | D6: 8.2 | E6: 18 | F6: 11 | G6: 18
A7: Dyson Daniels | B7: 122 | C7: 327 | D7: 9.9 | E7: 334 | F7: 228 | G7: 53
A8: Garrison Mathews | B8: 14 | C8: 75 | D8: 6.8 | E8: 61 | F8: 28 | G8: 14
A9: Georges Niang | B9: 47 | C9: 221 | D9: 7.1 | E9: 111 | F9: 32 | G9: 16
A10: Jacob Toppin | B10: 3 | C10: 12 | D10: 9 | E10: 7 | F10: 2 | G10: 0
A11: Jalen Johnson | B11: 61 | C11: 299 | D11: 13.5 | E11: 180 | F11: 58 | G11: 36
A12: Keaton Wallace | B12: 6 | C12: 43 | D12: 7.4 | E12: 81 | F12: 28 | G12: 9
A13: Kobe Bufkin | B13: 5 | C13: 16 | D13: 8.6 | E13: 17 | F13: 3 | G13: 2
... A374: Kelly Olynyk | B374: 62 | C374: 145 | D374: 9.8 | E374: 128 | F374: 35 | G374: 18
A375: Kylor Kelley | B375: 12 | C375: 28 | D375: 7.2 | E375: 6 | F375: 1 | G375: 3 | K375: Analyse des rebonds
A376: Lester Quinones | B376: 4 | C376: 16 | D376: 6.5 | E376: 23 | F376: 3 | G376: 3 | Z376: Analyse des passes décisives, interceptions et contres
A377: Mo Bamba | B377: 32 | C377: 112 | D377: 10 | E377: 19 | F377: 10 | G377: 32 | L377: Somme de OREB | M377: Somme de DREB | N377: Somme de PIE | AB377: Somme de AST | AC377: Somme de STL | AD377: Somme de BLK | AE377: Somme de PIE
A378: Trey Murphy III | B378: 48 | C378: 223 | D378: 11 | E378: 186 | F378: 58 | G378: 37 | K378: OKC | L378: 879 | M378: 2806 | N378: 160.5 | Z378: OKC | AB378: 2195 | AC378: 840 | AD378: 458 | AE378: 160.5
A379: Yves Missi | B379: 256 | C379: 343 | D379: 9 | E379: 102 | F379: 37 | G379: 95 | K379: Aaron Wiggins | L379: 84 | M379: 213 | N379: 10.5 | Z379: Aaron Wiggins | AB379: 137 | AC379: 61 | AD379: 15 | AE379: 10.5
A380: Zion Williamson | B380: 75 | C380: 141 | D380: 16.7 | E380: 159 | F380: 36 | G380: 27 | K380: Adam Flagler | L380: 7 | M380: 19 | N380: 2.5 | Z380: Adam Flagler | AB380: 11 | AC380: 7 | AD380: 4 | AE380: 2.5
A381: NYK | B381: 863 | C381: 2587 | D381: 157 | E381: 2282 | F381: 679 | G381: 323 | K381: Ajay Mitchell | L381: 18 | M381: 50 | N381: 8.2 | Z381: Ajay Mitchell | AB381: 65 | AC381: 25 | AD381: 4 | AE381: 8.2
A382: Anton Watson | B382: 1 | C382: 2 | D382: 3.3 | E382: 2 | F382: 1 | G382: 0 | K382: Alex Caruso | L382: 38 | M382: 119 | N382: 10.1 | Z382: Alex Caruso | AB382: 135 | AC382: 86 | AD382: 32 | AE382: 10.1
A383: Ariel Hukporti | B383: 15 | C383: 38 | D383: 4.8 | E383: 10 | F383: 0 | G383: 15 | K383: Alex Ducas | L383: 8 | M383: 17 | N383: 6.5 | Z383: Alex Ducas | AB383: 4 | AC383: 4 | AD383: 0 | AE383: 6.5
A384: Cameron Payne | B384: 14 | C384: 94 | D384: 8.9 | E384: 202 | F384: 36 | G384: 14 | K384: Branden Carlson | L384: 16 | M384: 38 | N384: 10.1 | Z384: Branden Carlson | AB384: 13 | AC384: 6 | AD384: 22 | AE384: 10.1
A385: Delon Wright | B385: 28 | C385: 40 | D385: 6.1 | E385: 76 | F385: 36 | G385: 12 | K385: Cason Wallace | L385: 68 | M385: 156 | N385: 7.5 | Z385: Cason Wallace | AB385: 170 | AC385: 122 | AD385: 34 | AE385: 7.5
A386: Jalen Brunson | B386: 26 | C386: 163 | D386: 13.8 | E386: 475 | F386: 59 | G386: 7 | K386: Chet Holmgren | L386: 48 | M386: 208 | N386: 12.2 | Z386: Chet Holmgren | AB386: 64 | AC386: 22 | AD386: 70 | AE386: 12.2
A387: Josh Hart | B387: 162 | C387: 578 | D387: 11.9 | E387: 454 | F387: 116 | G387: 31 | K387: Dillon Jones | L387: 32 | M387: 92 | N387: 6.6 | Z387: Dillon Jones | AB387: 59 | AC387: 16 | AD387: 5 | AE387: 6.6
A388: Karl-Anthony Towns | B388: 209 | C388: 706 | D388: 16.1 | E388: 223 | F388: 72 | G388: 50 | K388: Isaiah Hartenstein | L388: 165 | M388: 450 | N388: 13.8 | Z388: Isaiah Hartenstein | AB388: 217 | AC388: 46 | AD388: 63 | AE388: 13.8
A389: Kevin McCullar Jr, | B389: 0 | C389: 8 | D389: 6.6 | E389: 2 | F389: 1 | G389: 1 | K389: Isaiah Joe | L389: 44 | M389: 155 | N389: 8.9 | Z389: Isaiah Joe | AB389: 118 | AC389: 44 | AD389: 7 | AE389: 8.9
... A396: OG Anunoby | B396: 96 | C396: 259 | D396: 9.3 | E396: 163 | F396: 111 | G396: 67 | K396: Shai Gilgeous-Alexander | L396: 68 | M396: 312 | N396: 19.9 | Z396: Shai Gilgeous-Alexander | AB396: 486 | AC396: 129 | AD396: 76 | AE396: 19.9
A397: P,J, Tucker | B397: 4 | C397: 4 | D397: 1.5 | E397: 0 | F397: 1 | G397: 1
A398: Pacôme Dadiet | B398: 4 | C398: 14 | D398: 4.7 | E398: 5 | F398: 4 | G398: 2
A399: Precious Achiuwa | B399: 103 | C399: 217 | D399: 9.2 | E399: 57 | F399: 46 | G399: 40
A400: Tyler Kolek | B400: 8 | C400: 21 | D400: 7.2 | E400: 70 | F400: 12 | G400: 4
A401: OKC | B401: 879 | C401: 2806 | D401: 160.5 | E401: 2195 | F401: 840 | G401: 458
A402: Aaron Wiggins | B402: 84 | C402: 213 | D402: 10.5 | E402: 137 | F402: 61 | G402: 15
A403: Adam Flagler | B403: 7 | C403: 19 | D403: 2.5 | E403: 11 | F403: 7 | G403: 4
A404: Ajay Mitchell | B404: 18 | C404: 50 | D404: 8.2 | E404: 65 | F404: 25 | G404: 4
A405: Alex Caruso | B405: 38 | C405: 119 | D405: 10.1 | E405: 135 | F405: 86 | G405: 32
A406: Alex Ducas | B406: 8 | C406: 17 | D406: 6.5 | E406: 4 | F406: 4 | G406: 0
...

Sheet Top 15
A1: Player | B1: Team | C1: PTS | D1: FGM | E1: FGA | F1: FG% | G1: 3PA | H1: 3P% | I1: FTM | J1: FTA | K1: FT% | L1: OREB | M1: PIE
A2: Shai Gilgeous-Alexander | B2: OKC | C2: 2485 | D2: 859 | E2: 1657 | F2: 51.9 | G2: 433 | H2: 37.5 | I2: 600 | J2: 669 | K2: 89.8 | L2: 68 | M2: 19.9
A3: Anthony Edwards | B3: MIN | C3: 2180 | D3: 719 | E3: 1612 | F3: 44.7 | G3: 814 | H3: 39.5 | I3: 419 | J3: 498 | K3: 83.7 | L3: 63 | M3: 14
A4: Nikola Jokić | B4: DEN | C4: 2072 | D4: 784 | E4: 1365 | F4: 57.6 | G4: 329 | H4: 41.7 | I4: 364 | J4: 448 | K4: 80 | L4: 203 | M4: 20.6
A5: Giannis Antetokounmpo | B5: MIL | C5: 2037 | D5: 791 | E5: 1320 | F5: 60.1 | G5: 60 | H5: 22.2 | I5: 436 | J5: 710 | K5: 61.7 | L5: 147 | M5: 21
A6: Jayson Tatum | B6: BOS | C6: 1930 | D6: 662 | E6: 1462 | F6: 45.2 | G6: 727 | H6: 34.3 | I6: 360 | J6: 439 | K6: 81.4 | L6: 50 | M6: 15.8
A7: Devin Booker | B7: PHX | C7: 1920 | D7: 653 | E7: 1418 | F7: 46.1 | G7: 548 | H7: 33.2 | I7: 435 | J7: 480 | K7: 89.4 | L7: 75 | M7: 12.2
A8: Tyler Herro | B8: MIA | C8: 1840 | D8: 655 | E8: 1378 | F8: 47.2 | G8: 670 | H8: 37.5 | I8: 285 | J8: 323 | K8: 87.8 | L8: 39 | M8: 13.9
A9: Trae Young | B9: ATL | C9: 1839 | D9: 562 | E9: 1376 | F9: 41.1 | G9: 638 | H9: 34 | I9: 494 | J9: 562 | K9: 87.5 | L9: 38 | M9: 12.9
A10: Cade Cunningham | B10: DET | C10: 1827 | D10: 686 | E10: 1456 | F10: 46.9 | G10: 420 | H10: 35.6 | I10: 315 | J10: 371 | K10: 84.6 | L10: 56 | M10: 15.2
A11: James Harden | B11: LAC | C11: 1801 | D11: 529 | E11: 1296 | F11: 41 | G11: 672 | H11: 35.2 | I11: 506 | J11: 577 | K11: 87.4 | L11: 55 | M11: 14.5
A12: Karl-Anthony Towns | B12: NYK | C12: 1757 | D12: 641 | E12: 1217 | F12: 52.6 | G12: 338 | H12: 42 | I12: 338 | J12: 410 | K12: 82.9 | L12: 209 | M12: 16.1
A13: Zach LaVine | B13: SAC | C13: 1724 | D13: 622 | E13: 1221 | F13: 51.1 | G13: 533 | H13: 44.6 | I13: 237 | J13: 289 | K13: 82.5 | L13: 22 | M13: 11.5
... A570: Jalen McDaniels | B570: WAS | C570: 0 | D570: 0 | E570: 0 | F570: 0 | G570: 0 | H570: 0 | I570: 0 | J570: 0 | K570: 0 | L570: 0 | M570: 11.4

Sheet Calcul des ratios
A1: Player | B1: Team | C1: % True Shooting | D1: Ratio Passe vs Erreur | E1: PTS | F1: FGM | G1: FGA | H1: FG% | I1: 3PA | J1: 3P% | K1: FTM | L1: FTA | M1: FT% | N1: OREB | O1: DREB | P1: REB | Q1: AST | R1: TOV | S1: STL | T1: BLK | U1: PF | V1: FP | W1: DD2 | X1: TD3 | Y1: ="+/-" -> +/- | Z1: OFFRTG | AA1: DEFRTG | AB1: NETRTG | AC1: AST% | AD1: AST/TO | AE1: AST RATIO | AF1: OREB% | AG1: DREB% | AH1: REB% | AI1: TO RATIO | AJ1: EFG% | AK1: TS% | AL1: USG% | AM1: PACE | AN1: PIE | AO1: POSS
A2: Shai Gilgeous-Alexander | B2: OKC | C2: =IFERROR((E2/(2*(G2+0.44*L2))),"NA") -> 0.63673541 | D2: =IFERROR(Q2/R2,"NA") -> 2.6703297 | E2: 2485 | F2: 859 | G2: 1657 | H2: 51.9 | I2: 433 | J2: 37.5 | K2: 600 | L2: 669 | M2: 89.8 | N2: 68 | O2: 312 | P2: 380 | Q2: 486 | R2: 182 | S2: 129 | T2: 76 | U2: 167 | V2: 4112 | W2: 6 | X2: 0 | Y2: 12.1 | Z2: 122.4 | AA2: 105.7 | AB2: 16.7 | AC2: 29.9 | AD2: 2.66 | AE2: 18.7 | AF2: 2.5 | AG2: 11.2 | AH2: 6.9 | AI2: 7 | AJ2: 56.9 | AK2: 63.7 | AL2: 33.6 | AM2: 101.91 | AN2: 19.9 | AO2: 5514
A3: Anthony Edwards | B3: MIN | C3: =IFERROR((E3/(2*(G3+0.44*L3))),"NA") -> 0.5952641 | D3: =IFERROR(Q3/R3,"NA") -> 1.4071146 | E3: 2180 | F3: 719 | G3: 1612 | H3: 44.7 | I3: 814 | J3: 39.5 | K3: 419 | L3: 498 | M3: 83.7 | N3: 63 | O3: 387 | P3: 450 | Q3: 356 | R3: 253 | S3: 95 | T3: 47 | U3: 150 | V3: 3429 | W3: 7 | X3: 0 | Y3: 3.7 | Z3: 116.2 | AA3: 111.4 | AB3: 4.8 | AC3: 20.9 | AD3: 1.44 | AE3: 14.8 | AF3: 2.1 | AG3: 13.1 | AH3: 7.7 | AI3: 10.3 | AJ3: 54.7 | AK3: 59.5 | AL3: 30.7 | AM3: 98.27 | AN3: 14 | AO3: 5883
A4: Nikola Jokić | B4: DEN | C4: =IFERROR((E4/(2*(G4+0.44*L4))),"NA") -> 0.66320129 | D4: =IFERROR(Q4/R4,"NA") -> 3.0909091 | E4: 2072 | F4: 784 | G4: 1365 | H4: 57.6 | I4: 329 | J4: 41.7 | K4: 364 | L4: 448 | M4: 80 | N4: 203 | O4: 693 | P4: 889 | Q4: 714 | R4: 231 | S4: 126 | T4: 42 | U4: 161 | V4: 4501 | W4: 59 | X4: 34 | Y4: 8.5 | Z4: 125.6 | AA4: 115.1 | AB4: 10.5 | AC4: 39.8 | AD4: 3.11 | AE4: 28.7 | AF4: 8.3 | AG4: 25.2 | AH4: 17.3 | AI4: 9.2 | AJ4: 62.7 | AK4: 66.3 | AL4: 28.5 | AM4: 101.99 | AN4: 20.6 | AO4: 5471
A5: Giannis Antetokounmpo | B5: MIL | C5: =IFERROR((E5/(2*(G5+0.44*L5))),"NA") -> 0.62392796 | D5: =IFERROR(Q5/R5,"NA") -> 2.0961538 | E5: 2037 | F5: 791 | G5: 1320 | H5: 60.1 | I5: 60 | J5: 22.2 | K5: 436 | L5: 710 | M5: 61.7 | N5: 147 | O5: 650 | P5: 797 | Q5: 436 | R5: 208 | S5: 60 | T5: 80 | U5: 154 | V5: 3846 | W5: 55 | X5: 11 | Y5: 5 | Z5: 118.9 | AA5: 111.7 | AB5: 7.2 | AC5: 33.9 | AD5: 2.1 | AE5: 19.2 | AF5: 6.7 | AG5: 26.6 | AH5: 17.2 | AI5: 9.1 | AJ5: 60.7 | AK5: 62.5 | AL5: 34.6 | AM5: 100.18 | AN5: 21 | AO5: 4772
A6: Jayson Tatum | B6: BOS | C6: =IFERROR((E6/(2*(G6+0.44*L6))),"NA") -> 0.58302521 | D6: =IFERROR(Q6/R6,"NA") -> 2.0669856 | E6: 1930 | F6: 662 | G6: 1462 | H6: 45.2 | I6: 727 | J6: 34.3 | K6: 360 | L6: 439 | M6: 81.4 | N6: 50 | O6: 576 | P6: 626 | Q6: 432 | R6: 209 | S6: 79 | T6: 36 | U6: 158 | V6: 3456 | W6: 31 | X6: 2 | Y6: 7.4 | Z6: 119.6 | AA6: 109.8 | AB6: 9.8 | AC6: 26.6 | AD6: 2.6 | AE6: 18.9 | AF6: 1.7 | AG6: 20.6 | AH6: 11.2 | AI6: 9.2 | AJ6: 53.7 | AK6: 58.2 | AL6: 30.1 | AM6: 98.14 | AN6: 15.8 | AO6: 5368
A7: Devin Booker | B7: PHX | C7: =IFERROR((E7/(2*(G7+0.44*L7))),"NA") -> 0.58924626 | D7: =IFERROR(Q7/R7,"NA") -> 2.4449541 | E7: 1920 | F7: 653 | G7: 1418 | H7: 46.1 | I7: 548 | J7: 33.2 | K7: 435 | L7: 480 | M7: 89.4 | N7: 75 | O7: 233 | P7: 308 | Q7: 533 | R7: 218 | S7: 68 | T7: 15 | U7: 195 | V7: 3113 | W7: 16 | X7: 0 | Y7: -2.4 | Z7: 115.3 | AA7: 118.5 | AB7: -3.2 | AC7: 30.1 | AD7: 2.4 | AE7: 22.4 | AF7: 2.8 | AG7: 8 | AH7: 5.5 | AI7: 9.3 | AJ7: 52.5 | AK7: 58.9 | AL7: 28.5 | AM7: 98.72 | AN7: 12.2 | AO7: 5752
A8: Tyler Herro | B8: MIA | C8: =IFERROR((E8/(2*(G8+0.44*L8))),"NA") -> 0.60521538 | D8: =IFERROR(Q8/R8,"NA") -> 2.12 | E8: 1840 | F8: 655 | G8: 1378 | H8: 47.2 | I8: 670 | J8: 37.5 | K8: 285 | L8: 323 | M8: 87.8 | N8: 39 | O8: 362 | P8: 400 | Q8: 424 | R8: 200 | S8: 69 | T8: 15 | U8: 85 | V8: 3018 | W8: 9 | X8: 0 | Y8: 1.3 | Z8: 113.9 | AA8: 112.6 | AB8: 1.3 | AC8: 25.4 | AD8: 2.14 | AE8: 20 | AF8: 1.3 | AG8: 13.2 | AH8: 7.3 | AI8: 9.3 | AJ8: 56.3 | AK8: 60.5 | AL8: 27.1 | AM8: 97.78 | AN8: 13.9 | AO8: 5564
A9: Trae Young | B9: ATL | C9: =IFERROR((E9/(2*(G9+0.44*L9))),"NA") -> 0.56644571 | D9: =IFERROR(Q9/R9,"NA") -> 2.4705882 | E9: 1839 | F9: 562 | G9: 1376 | H9: 41.1 | I9: 638 | J9: 34 | K9: 494 | L9: 562 | M9: 87.5 | N9: 38 | O9: 198 | P9: 236 | Q9: 882 | R9: 357 | S9: 91 | T9: 15 | U9: 144 | V9: 3397 | W9: 51 | X9: 0 | Y9: 0.4 | Z9: 115.2 | AA9: 114.6 | AB9: 0.6 | AC9: 45.2 | AD9: 2.48 | AE9: 30.9 | AF9: 1.2 | AG9: 7.2 | AH9: 4.2 | AI9: 12.5 | AJ9: 49.1 | AK9: 56.7 | AL9: 28.5 | AM9: 105.51 | AN9: 12.9 | AO9: 6020
A10: Cade Cunningham | B10: DET | C10: =IFERROR((E10/(2*(G10+0.44*L10))),"NA") -> 0.56415355 | D10: =IFERROR(Q10/R10,"NA") -> 2.0681818 | E10: 1827 | F10: 686 | G10: 1456 | H10: 46.9 | I10: 420 | J10: 35.6 | K10: 315 | L10: 371 | M10: 84.6 | N10: 56 | O10: 371 | P10: 427 | Q10: 637 | R10: 308 | S10: 70 | T10: 56 | U10: 196 | V10: 3360 | W10: 31 | X10: 9 | Y10: 2.5 | Z10: 115 | AA10: 112.2 | AB10: 2.8 | AC10: 40.9 | AD10: 2.06 | AE10: 25 | AF10: 2.3 | AG10: 14.7 | AH10: 8.6 | AI10: 12.1 | AJ10: 52.1 | AK10: 56.5 | AL10: 32.3 | AM10: 101.57 | AN10: 15.2 | AO10: 5201
A11: James Harden | B11: LAC | C11: =IFERROR((E11/(2*(G11+0.44*L11))),"NA") -> 0.58101272 | D11: =IFERROR(Q11/R11,"NA") -> 2.0205882 | E11: 1801 | F11: 529 | G11: 1296 | H11: 41 | I11: 672 | J11: 35.2 | K11: 506 | L11: 577 | M11: 87.4 | N11: 55 | O11: 403 | P11: 458 | Q11: 687 | R11: 340 | S11: 119 | T11: 55 | U11: 166 | V11: 3555 | W11: 38 | X11: 3 | Y11: 4.4 | Z11: 115.4 | AA11: 109.2 | AB11: 6.2 | AC11: 36.5 | AD11: 2.01 | AE11: 26.9 | AF11: 2 | AG11: 14.3 | AH11: 8.3 | AI11: 13.4 | AJ11: 50.1 | AK11: 58.2 | AL11: 28.6 | AM11: 98.82 | AN11: 14.5 | AO11: 5737
A12: Karl-Anthony Towns | B12: NYK | C12: =IFERROR((E12/(2*(G12+0.44*L12))),"NA") -> 0.62866753 | D12: =IFERROR(Q12/R12,"NA") -> 1.1494845 | E12: 1757 | F12: 641 | G12: 1217 | H12: 52.6 | I12: 338 | J12: 42 | K12: 338 | L12: 410 | M12: 82.9 | N12: 209 | O12: 706 | P12: 922 | Q12: 223 | R12: 194 | S12: 72 | T12: 50 | U12: 252 | V12: 3370 | W12: 58 | X12: 1 | Y12: 5.3 | Z12: 119.4 | AA12: 112.7 | AB12: 6.8 | AC12: 13 | AD12: 1.16 | AE12: 12.4 | AF12: 8.7 | AG12: 28.4 | AH12: 18.7 | AI12: 10.7 | AJ12: 58.4 | AK12: 63 | AL12: 26.5 | AM12: 99.25 | AN12: 16.1 | AO12: 5215
A13: Zach LaVine | B13: SAC | C13: =IFERROR((E13/(2*(G13+0.44*L13))),"NA") -> 0.63938998 | D13: =IFERROR(Q13/R13,"NA") -> 1.5024155 | E13: 1724 | F13: 622 | G13: 1221 | H13: 51.1 | I13: 533 | J13: 44.6 | K13: 237 | L13: 289 | M13: 82.5 | N13: 22 | O13: 296 | P13: 318 | Q13: 311 | R13: 207 | S13: 59 | T13: 15 | U13: 118 | V13: 2568 | W13: 6 | X13: 0 | Y13: -0.9 | Z13: 115.4 | AA13: 116.8 | AB13: -1.4 | AC13: 17.8 | AD13: 1.49 | AE13: 16.7 | AF13: 0.9 | AG13: 10.7 | AH13: 5.9 | AI13: 11.2 | AJ13: 60.9 | AK13: 63.9 | AL13: 25.1 | AM13: 101.28 | AN13: 11.5 | AO13: 5493
... A548: Tazé Moore | B548: POR | C548: =IFERROR((E548/(2*(G548+0.44*L548))),"NA") -> 0.27573529 | D548: =IFERROR(Q548/R548,"NA") -> 0.5 | E548: 6 | F548: 2 | G548: 10 | H548: 20 | I548: 4 | J548: 25 | K548: 1 | L548: 2 | M548: 50 | N548: 4 | O548: 4 | P548: 8 | Q548: 1 | R548: 2 | S548: 2 | T548: 0 | U548: 0 | V548: 21 | W548: 0 | X548: 0 | Y548: -3.5 | Z548: 58.7 | AA548: 77.3 | AB548: -18.6 | AC548: 12.5 | AD548: 0.5 | AE548: 7.1 | AF548: 12.1 | AG548: 16 | AH548: 13.8 | AI548: 14.3 | AJ548: 25 | AK548: 27.6 | AL548: 22.4 | AM548: 108.82 | AN548: 10.5 | AO548: 46
A549: Alondes Williams | B549: DET | C549: NA | D549: =IFERROR(Q549/R549,"NA") -> NA | E549: 5 | F549: 2 | G549: 2 | H549: 100 | I549: 1 | J549: 100 | K549: 0 | L549: 0 | M549: 0 | N549: 0 | O549: 0 | P549: 0 | Q549: 1 | R549: 0 | S549: 0 | T549: 0 | U549: 0 | V549: 7 | W549: 0 | X549: 0 | Y549: 6 | Z549: 171.4 | AA549: 85.7 | AB549: 85.7 | AC549: 33.3 | AD549: 0 | AE549: 33.3 | AF549: 0 | AG549: 0 | AH549: 0 | AI549: 0 | AJ549: 125 | AK549: 125 | AL549: 28.6 | AM549: 90.4 | AN549: 40 | AO549: 7
A550: Skal Labissiere | B550: SAC | C550: =IFERROR((E550/(2*(G550+0.44*L550))),"NA") -> 0.625 | D550: =IFERROR(Q550/R550,"NA") -> NA | E550: 5 | F550: 2 | G550: 4 | H550: 50 | I550: 1 | J550: 100 | K550: 0 | L550: 0 | M550: 0 | N550: 1 | O550: 2 | P550: 3 | Q550: 1 | R550: 0 | S550: 0 | T550: 0 | U550: 1 | V550: 10 | W550: 0 | X550: 0 | Y550: -0.3 | Z550: 114.8 | AA550: 128 | AB550: -13.2 | AC550: 12.5 | AD550: 0 | AE550: 20 | AF550: 8.3 | AG550: 22.2 | AH550: 14.3 | AI550: 0 | AJ550: 62.5 | AK550: 62.5 | AL550: 12.9 | AM550: 104.35 | AN550: 9.2 | AO550: 27
A551: Ulrich Chomche | B551: TOR | C551: =IFERROR((E551/(2*(G551+0.44*L551))),"NA") -> 0.42517007 | D551: =IFERROR(Q551/R551,"NA") -> 1 | E551: 5 | F551: 2 | G551: 5 | H551: 40 | I551: 0 | J551: 0 | K551: 1 | L551: 2 | M551: 50 | N551: 4 | O551: 4 | P551: 8 | Q551: 2 | R551: 2 | S551: 0 | T551: 1 | U551: 5 | V551: 19 | W551: 0 | X551: 0 | Y551: -3.4 | Z551: 96.9 | AA551: 140.3 | AB551: -43.4 | AC551: 11.1 | AD551: 1 | AE551: 20 | AF551: 12.9 | AG551: 18.2 | AH551: 15.1 | AI551: 20 | AJ551: 40 | AK551: 42.5 | AL551: 10.8 | AM551: 94.73 | AN551: 2 | AO551: 65
A552: Ron Harper Jr, | B552: DET | C552: =IFERROR((E552/(2*(G552+0.44*L552))),"NA") -> 0.22522523 | D552: =IFERROR(Q552/R552,"NA") -> NA | E552: 4 | F552: 1 | G552: 8 | H552: 12.5 | I552: 6 | J552: 0 | K552: 2 | L552: 2 | M552: 100 | N552: 4 | O552: 3 | P552: 7 | Q552: 2 | R552: 0 | S552: 0 | T552: 0 | U552: 0 | V552: 15 | W552: 0 | X552: 0 | Y552: -1 | Z552: 120.6 | AA552: 116.7 | AB552: 3.9 | AC552: 14.3 | AD552: 0 | AE552: 18.2 | AF552: 18.2 | AG552: 20 | AH552: 18.9 | AI552: 0 | AJ552: 12.5 | AK552: 22.5 | AL552: 20.5 | AM552: 98.82 | AN552: 7.1 | AO552: 34
A553: Harrison Ingram | B553: SAS | C553: =IFERROR((E553/(2*(G553+0.44*L553))),"NA") -> 0.5 | D553: =IFERROR(Q553/R553,"NA") -> 3 | E553: 4 | F553: 2 | G553: 4 | H553: 50 | I553: 1 | J553: 0 | K553: 0 | L553: 0 | M553: 0 | N553: 2 | O553: 7 | P553: 9 | Q553: 3 | R553: 1 | S553: 3 | T553: 0 | U553: 2 | V553: 28 | W553: 0 | X553: 0 | Y553: 6 | Z553: 132 | AA553: 92 | AB553: 40 | AC553: 8.6 | AD553: 3 | AE553: 37.5 | AF553: 6.7 | AG553: 17.5 | AH553: 12.9 | AI553: 12.5 | AJ553: 50 | AK553: 50 | AL553: 6 | AM553: 103.6 | AN553: 8 | AO553: 75
A554: Cui Yongxi | B554: BKN | C554: =IFERROR((E554/(2*(G554+0.44*L554))),"NA") -> 0.19035533 | D554: =IFERROR(Q554/R554,"NA") -> NA | E554: 3 | F554: 1 | G554: 7 | H554: 14.3 | I554: 3 | J554: 0 | K554: 1 | L554: 2 | M554: 50 | N554: 0 | O554: 2 | P554: 2 | Q554: 0 | R554: 0 | S554: 0 | T554: 0 | U554: 0 | V554: 6 | W554: 0 | X554: 0 | Y554: 0.4 | Z554: 80.8 | AA554: 76 | AB554: 4.8 | AC554: 0 | AD554: 0 | AE554: 0 | AF554: 0 | AG554: 20 | AH554: 9.5 | AI554: 0 | AJ554: 14.3 | AK554: 19 | AL554: 29.6 | AM554: 118.62 | AN554: -5.6 | AO554: 26
A555: Braxton Key | B555: GSW | C555: =IFERROR((E555/(2*(G555+0.44*L555))),"NA") -> 0.22590361 | D555: =IFERROR(Q555/R555,"NA") -> 0 | E555: 3 | F555: 0 | G555: 4 | H555: 0 | I555: 1 | J555: 0 | K555: 3 | L555: 6 | M555: 50 | N555: 1 | O555: 1 | P555: 2 | Q555: 0 | R555: 1 | S555: 2 | T555: 0 | U555: 0 | V555: 11 | W555: 0 | X555: 0 | Y555: -2.7 | Z555: 90 | AA555: 120.7 | AB555: -30.7 | AC555: 0 | AD555: 0 | AE555: 0 | AF555: 7.7 | AG555: 16.7 | AH555: 10.5 | AI555: 12.5 | AJ555: 0 | AK555: 22.6 | AL555: 22.2 | AM555: 130.81 | AN555: -2.6 | AO555: 30
A556: Quincy Olivari | B556: LAL | C556: =IFERROR((E556/(2*(G556+0.44*L556))),"NA") -> 0.3 | D556: =IFERROR(Q556/R556,"NA") -> 1 | E556: 3 | F556: 1 | G556: 5 | H556: 20 | I556: 5 | J556: 20 | K556: 0 | L556: 0 | M556: 0 | N556: 0 | O556: 0 | P556: 0 | Q556: 1 | R556: 1 | S556: 0 | T556: 0 | U556: 0 | V556: 4 | W556: 0 | X556: 0 | Y556: -9 | Z556: 68.2 | AA556: 150 | AB556: -81.8 | AC556: 20 | AD556: 1 | AE556: 14.3 | AF556: 0 | AG556: 0 | AH556: 0 | AI556: 14.3 | AJ556: 30 | AK556: 30 | AL556: 23.1 | AM556: 102.52 | AN556: -2.2 | AO556: 22
A557: Tristen Newton | B557: MIN | C557: =IFERROR((E557/(2*(G557+0.44*L557))),"NA") -> 0.17772512 | D557: =IFERROR(Q557/R557,"NA") -> 1 | E557: 3 | F557: 1 | G557: 8 | H557: 12.5 | I557: 3 | J557: 0 | K557: 1 | L557: 1 | M557: 100 | N557: 2 | O557: 2 | P557: 4 | Q557: 2 | R557: 2 | S557: 1 | T557: 0 | U557: 4 | V557: 12 | W557: 0 | X557: 0 | Y557: -0.6 | Z557: 83.3 | AA557: 97.6 | AB557: -14.2 | AC557: 18.2 | AD557: 1 | AE557: 16.7 | AF557: 7.1 | AG557: 11.1 | AH557: 8.7 | AI557: 16.7 | AJ557: 12.5 | AK557: 17.8 | AL557: 18.5 | AM557: 123.38 | AN557: -6.8 | AO557: 42
A558: D,J, Carton | B558: TOR | C558: =IFERROR((E558/(2*(G558+0.44*L558))),"NA") -> 0.2016129 | D558: =IFERROR(Q558/R558,"NA") -> 0.75 | E558: 3 | F558: 1 | G558: 7 | H558: 14.3 | I558: 3 | J558: 0 | K558: 1 | L558: 1 | M558: 100 | N558: 0 | O558: 4 | P558: 4 | Q558: 3 | R558: 4 | S558: 2 | T558: 0 | U558: 1 | V558: 14 | W558: 0 | X558: 0 | Y558: 3 | Z558: 109 | AA558: 96.1 | AB558: 12.9 | AC558: 10 | AD558: 0.75 | AE558: 21.4 | AF558: 0 | AG558: 9.8 | AH558: 5.5 | AI558: 28.6 | AJ558: 14.3 | AK558: 20.2 | AL558: 12.2 | AM558: 110.7 | AN558: 0.7 | AO558: 78
A559: Yuri Collins | B559: GSW | C559: =IFERROR((E559/(2*(G559+0.44*L559))),"NA") -> 0.33333333 | D559: =IFERROR(Q559/R559,"NA") -> NA | E559: 2 | F559: 1 | G559: 3 | H559: 33.3 | I559: 0 | J559: 0 | K559: 0 | L559: 0 | M559: 0 | N559: 2 | O559: 1 | P559: 3 | Q559: 4 | R559: 0 | S559: 2 | T559: 0 | U559: 5 | V559: 18 | W559: 0 | X559: 0 | Y559: -2.5 | Z559: 94.4 | AA559: 111.4 | AB559: -17 | AC559: 33.3 | AD559: 0 | AE559: 57.1 | AF559: 8.3 | AG559: 7.1 | AH559: 7.9 | AI559: 0 | AJ559: 33.3 | AK559: 33.3 | AL559: 6.8 | AM559: 104.54 | AN559: 4.8 | AO559: 36
A560: Malevy Leons | B560: OKC | C560: =IFERROR((E560/(2*(G560+0.44*L560))),"NA") -> 0.26595745 | D560: =IFERROR(Q560/R560,"NA") -> 1 | E560: 2 | F560: 0 | G560: 2 | H560: 0 | I560: 1 | J560: 0 | K560: 2 | L560: 4 | M560: 50 | N560: 1 | O560: 2 | P560: 3 | Q560: 1 | R560: 1 | S560: 0 | T560: 0 | U560: 4 | V560: 6 | W560: 0 | X560: 0 | Y560: -3 | Z560: 61.4 | AA560: 104.7 | AB560: -43.3 | AC560: 11.1 | AD560: 1 | AE560: 16.7 | AF560: 4 | AG560: 9.5 | AH560: 6.5 | AI560: 16.7 | AJ560: 0 | AK560: 26.6 | AL560: 10.2 | AM560: 99.59 | AN560: -6.9 | AO560: 44
A561: Daishen Nix | B561: MIN | C561: =IFERROR((E561/(2*(G561+0.44*L561))),"NA") -> 0.26595745 | D561: =IFERROR(Q561/R561,"NA") -> 0.75 | E561: 1 | F561: 0 | G561: 1 | H561: 0 | I561: 1 | J561: 0 | K561: 1 | L561: 2 | M561: 50 | N561: 0 | O561: 4 | P561: 4 | Q561: 3 | R561: 4 | S561: 0 | T561: 0 | U561: 1 | V561: 6 | W561: 0 | X561: 0 | Y561: 3 | Z561: 103.2 | AA561: 79.3 | AB561: 23.9 | AC561: 23.1 | AD561: 0.75 | AE561: 33.3 | AF561: 0 | AG561: 44.4 | AH561: 21.1 | AI561: 44.4 | AJ561: 0 | AK561: 26.6 | AL561: 17.6 | AM561: 108.82 | AN561: 2.4 | AO561: 31
... A570: Jalen McDaniels | B570: WAS | C570: =IFERROR((E570/(2*(G570+0.44*L570))),"NA") -> NA | D570: =IFERROR(Q570/R570,"NA") -> NA | E570: 0 | F570: 0 | G570: 0 | H570: 0 | I570: 0 | J570: 0 | K570: 0 | L570: 0 | M570: 0 | N570: 0 | O570: 0 | P570: 0 | Q570: 1 | R570: 0 | S570: 1 | T570: 0 | U570: 0 | V570: 4 | W570: 0 | X570: 0 | Y570: -0.3 | Z570: 81.3 | AA570: 77.8 | AB570: 3.5 | AC570: 25 | AD570: 0 | AE570: 100 | AF570: 0 | AG570: 0 | AH570: 0 | AI570: 0 | AJ570: 0 | AK570: 0 | AL570: 0 | AM570: 111.25 | AN570: 11.4 | AO570: 16

Sheet Classements
A1: Equipes le plus souvent gagnantes
A3: Étiquettes de lignes | B3: Somme de W | D3: Étiquettes de lignes | E3: Somme de W
A4: OKC | B4: 767 | D4: OKC | E4: 767
A5: CLE | B5: 671 | D5: CLE | E5: 671
A6: BOS | B6: 628 | D6: BOS | E6: 628
A7: HOU | B7: 562 | D7: HOU | E7: 562
A8: IND | B8: 556 | D8: IND | E8: 556
A9: MIN | B9: 548 | D9: MIN | E9: 548
A10: MIL | B10: 535 | D10: MIL | E10: 535
A11: DEN | B11: 521 | D11: DEN | E11: 521
A12: LAL | B12: 520 | D12: LAL | E12: 520
A13: NYK | B13: 514 | D13: NYK | E13: 514
A14: LAC | B14: 505 | D14: LAC | E14: 505
A15: GSW | B15: 498 | D15: GSW | E15: 498
... A33: UTA | B33: 190 | D33: UTA | E33: 190
A34: Total général | B34: 13221
A38: Classement par efficacité individuelle
A39: Team | B39: (Tous)
A41: Étiquettes de lignes | B41: Moyenne de % True Shooting | C41: Moyenne de Ratio Passe vs Erreur | F41: Étiquettes de lignes | G41: Moyenne de % True Shooting | H41: Moyenne de Ratio Passe vs Erreur
A42: Jahmir Young | B42: 0.93537415 | C42: 6 | F42: Jahmir Young | G42: 0.93537415 | H42: 6
A43: Daeqwon Plowden | B43: 0.83075734 | C43: 0.5 | F43: Daeqwon Plowden | G43: 0.83075734 | H43: 0.5
A44: Kai Jones | B44: 0.81913499 | C44: 1.2 | F44: Kai Jones | G44: 0.81913499 | H44: 1.2
A45: N'Faly Dante | B45: 0.78947368 | C45: 1 | F45: N'Faly Dante | G45: 0.78947368 | H45: 1
A46: Jarrett Allen | B46: 0.7256542 | C46: 1.5918367 | F46: Jarrett Allen | G46: 0.7256542 | H46: 1.5918367
A47: Dwight Powell | B47: 0.72175212 | C47: 3.2352941 | F47: Dwight Powell | G47: 0.72175212 | H47: 3.2352941
A48: Adem Bona | B48: 0.71623465 | C48: 0.453125 | F48: Adem Bona | G48: 0.71623465 | H48: 0.453125
A49: Daniel Gafford | B49: 0.71478098 | C49: 1.1764706 | F49: Daniel Gafford | G49: 0.71478098 | H49: 1.1764706
A50: Jaxson Hayes | B50: 0.70965579 | C50: 1.2444444 | F50: Jaxson Hayes | G50: 0.70965579 | H50: 1.2444444
A51: Keshad Johnson | B51: 0.70723684 | C51: 1 | F51: Keshad Johnson | G51: 0.70723684 | H51: 1
A52: Jalen Duren | B52: 0.70500245 | C52: 1.5864662 | F52: Jalen Duren | G52: 0.70500245 | H52: 1.5864662
A53: Dereck Lively II | B53: 0.70280223 | C53: 2.15 | F53: Dereck Lively II | G53: 0.70280223 | H53: 2.15
... A56: Richaun Holmes | B56: 0.68992528 | C56: 1.9545455 | F56: Richaun Holmes | G56: 0.68992528 | H56: 1.9545455
A57: Bobi Klintman | B57: 0.68933824 | C57: 7
A58: Luke Kornet | B58: 0.68695107 | C58: 4.0344828
A59: Rudy Gobert | B59: 0.68402052 | C59: 1.5116279
A60: Isaac Jones | B60: 0.68108974 | C60: 0.75
A61: Tolu Smith | B61: 0.67829457 | C61: 0
A62: Mitchell Robinson | B62: 0.67588564 | C62: 1.4
A63: Robert Williams III | B63: 0.67504655 | C63: 1.2222222
A64: Ariel Hukporti | B64: 0.6718925 | C64: 0.5
...

Sheet Données NBA
A1: Player | B1: Team | C1: PTS | D1: FGM | E1: FGA | F1: FG% | G1: 3PA | H1: 3P% | I1: FTM | J1: FTA | K1: FT% | L1: OREB | M1: DREB | N1: REB | O1: AST | P1: TOV | Q1: STL | R1: BLK | S1: PF | T1: FP | U1: DD2 | V1: TD3 | W1: ="+/-" -> +/- | X1: OFFRTG | Y1: DEFRTG | Z1: NETRTG | AA1: AST% | AB1: AST/TO | AC1: AST RATIO | AD1: OREB% | AE1: DREB% | AF1: REB% | AG1: TO RATIO | AH1: EFG% | AI1: TS% | AJ1: USG% | AK1: PACE | AL1: PIE | AM1: POSS
A2: Shai Gilgeous-Alexander | B2: OKC | C2: 2485 | D2: 859 | E2: 1657 | F2: 51.9 | G2: 433 | H2: 37.5 | I2: 600 | J2: 669 | K2: 89.8 | L2: 68 | M2: 312 | N2: 380 | O2: 486 | P2: 182 | Q2: 129 | R2: 76 | S2: 167 | T2: 4112 | U2: 6 | V2: 0 | W2: 12.1 | X2: 122.4 | Y2: 105.7 | Z2: 16.7 | AA2: 29.9 | AB2: 2.66 | AC2: 18.7 | AD2: 2.5 | AE2: 11.2 | AF2: 6.9 | AG2: 7 | AH2: 56.9 | AI2: 63.7 | AJ2: 33.6 | AK2: 101.91 | AL2: 19.9 | AM2: 5514
A3: Anthony Edwards | B3: MIN | C3: 2180 | D3: 719 | E3: 1612 | F3: 44.7 | G3: 814 | H3: 39.5 | I3: 419 | J3: 498 | K3: 83.7 | L3: 63 | M3: 387 | N3: 450 | O3: 356 | P3: 253 | Q3: 95 | R3: 47 | S3: 150 | T3: 3429 | U3: 7 | V3: 0 | W3: 3.7 | X3: 116.2 | Y3: 111.4 | Z3: 4.8 | AA3: 20.9 | AB3: 1.44 | AC3: 14.8 | AD3: 2.1 | AE3: 13.1 | AF3: 7.7 | AG3: 10.3 | AH3: 54.7 | AI3: 59.5 | AJ3: 30.7 | AK3: 98.27 | AL3: 14 | AM3: 5883
A4: Nikola Jokić | B4: DEN | C4: 2072 | D4: 784 | E4: 1365 | F4: 57.6 | G4: 329 | H4: 41.7 | I4: 364 | J4: 448 | K4: 80 | L4: 203 | M4: 693 | N4: 889 | O4: 714 | P4: 231 | Q4: 126 | R4: 42 | S4: 161 | T4: 4501 | U4: 59 | V4: 34 | W4: 8.5 | X4: 125.6 | Y4: 115.1 | Z4: 10.5 | AA4: 39.8 | AB4: 3.11 | AC4: 28.7 | AD4: 8.3 | AE4: 25.2 | AF4: 17.3 | AG4: 9.2 | AH4: 62.7 | AI4: 66.3 | AJ4: 28.5 | AK4: 101.99 | AL4: 20.6 | AM4: 5471
A5: Giannis Antetokounmpo | B5: MIL | C5: 2037 | D5: 791 | E5: 1320 | F5: 60.1 | G5: 60 | H5: 22.2 | I5: 436 | J5: 710 | K5: 61.7 | L5: 147 | M5: 650 | N5: 797 | O5: 436 | P5: 208 | Q5: 60 | R5: 80 | S5: 154 | T5: 3846 | U5: 55 | V5: 11 | W5: 5 | X5: 118.9 | Y5: 111.7 | Z5: 7.2 | AA5: 33.9 | AB5: 2.1 | AC5: 19.2 | AD5: 6.7 | AE5: 26.6 | AF5: 17.2 | AG5: 9.1 | AH5: 60.7 | AI5: 62.5 | AJ5: 34.6 | AK5: 100.18 | AL5: 21 | AM5: 4772
A6: Jayson Tatum | B6: BOS | C6: 1930 | D6: 662 | E6: 1462 | F6: 45.2 | G6: 727 | H6: 34.3 | I6: 360 | J6: 439 | K6: 81.4 | L6: 50 | M6: 576 | N6: 626 | O6: 432 | P6: 209 | Q6: 79 | R6: 36 | S6: 158 | T6: 3456 | U6: 31 | V6: 2 | W6: 7.4 | X6: 119.6 | Y6: 109.8 | Z6: 9.8 | AA6: 26.6 | AB6: 2.6 | AC6: 18.9 | AD6: 1.7 | AE6: 20.6 | AF6: 11.2 | AG6: 9.2 | AH6: 53.7 | AI6: 58.2 | AJ6: 30.1 | AK6: 98.14 | AL6: 15.8 | AM6: 5368
A7: Devin Booker | B7: PHX | C7: 1920 | D7: 653 | E7: 1418 | F7: 46.1 | G7: 548 | H7: 33.2 | I7: 435 | J7: 480 | K7: 89.4 | L7: 75 | M7: 233 | N7: 308 | O7: 533 | P7: 218 | Q7: 68 | R7: 15 | S7: 195 | T7: 3113 | U7: 16 | V7: 0 | W7: -2.4 | X7: 115.3 | Y7: 118.5 | Z7: -3.2 | AA7: 30.1 | AB7: 2.4 | AC7: 22.4 | AD7: 2.8 | AE7: 8 | AF7: 5.5 | AG7: 9.3 | AH7: 52.5 | AI7: 58.9 | AJ7: 28.5 | AK7: 98.72 | AL7: 12.2 | AM7: 5752
A8: Tyler Herro | B8: MIA | C8: 1840 | D8: 655 | E8: 1378 | F8: 47.2 | G8: 670 | H8: 37.5 | I8: 285 | J8: 323 | K8: 87.8 | L8: 39 | M8: 362 | N8: 400 | O8: 424 | P8: 200 | Q8: 69 | R8: 15 | S8: 85 | T8: 3018 | U8: 9 | V8: 0 | W8: 1.3 | X8: 113.9 | Y8: 112.6 | Z8: 1.3 | AA8: 25.4 | AB8: 2.14 | AC8: 20 | AD8: 1.3 | AE8: 13.2 | AF8: 7.3 | AG8: 9.3 | AH8: 56.3 | AI8: 60.5 | AJ8: 27.1 | AK8: 97.78 | AL8: 13.9 | AM8: 5564
A9: Trae Young | B9: ATL | C9: 1839 | D9: 562 | E9: 1376 | F9: 41.1 | G9: 638 | H9: 34 | I9: 494 | J9: 562 | K9: 87.5 | L9: 38 | M9: 198 | N9: 236 | O9: 882 | P9: 357 | Q9: 91 | R9: 15 | S9: 144 | T9: 3397 | U9: 51 | V9: 0 | W9: 0.4 | X9: 115.2 | Y9: 114.6 | Z9: 0.6 | AA9: 45.2 | AB9: 2.48 | AC9: 30.9 | AD9: 1.2 | AE9: 7.2 | AF9: 4.2 | AG9: 12.5 | AH9: 49.1 | AI9: 56.7 | AJ9: 28.5 | AK9: 105.51 | AL9: 12.9 | AM9: 6020
A10: Cade Cunningham | B10: DET | C10: 1827 | D10: 686 | E10: 1456 | F10: 46.9 | G10: 420 | H10: 35.6 | I10: 315 | J10: 371 | K10: 84.6 | L10: 56 | M10: 371 | N10: 427 | O10: 637 | P10: 308 | Q10: 70 | R10: 56 | S10: 196 | T10: 3360 | U10: 31 | V10: 9 | W10: 2.5 | X10: 115 | Y10: 112.2 | Z10: 2.8 | AA10: 40.9 | AB10: 2.06 | AC10: 25 | AD10: 2.3 | AE10: 14.7 | AF10: 8.6 | AG10: 12.1 | AH10: 52.1 | AI10: 56.5 | AJ10: 32.3 | AK10: 101.57 | AL10: 15.2 | AM10: 5201
A11: James Harden | B11: LAC | C11: 1801 | D11: 529 | E11: 1296 | F11: 41 | G11: 672 | H11: 35.2 | I11: 506 | J11: 577 | K11: 87.4 | L11: 55 | M11: 403 | N11: 458 | O11: 687 | P11: 340 | Q11: 119 | R11: 55 | S11: 166 | T11: 3555 | U11: 38 | V11: 3 | W11: 4.4 | X11: 115.4 | Y11: 109.2 | Z11: 6.2 | AA11: 36.5 | AB11: 2.01 | AC11: 26.9 | AD11: 2 | AE11: 14.3 | AF11: 8.3 | AG11: 13.4 | AH11: 50.1 | AI11: 58.2 | AJ11: 28.6 | AK11: 98.82 | AL11: 14.5 | AM11: 5737
A12: Karl-Anthony Towns | B12: NYK | C12: 1757 | D12: 641 | E12: 1217 | F12: 52.6 | G12: 338 | H12: 42 | I12: 338 | J12: 410 | K12: 82.9 | L12: 209 | M12: 706 | N12: 922 | O12: 223 | P12: 194 | Q12: 72 | R12: 50 | S12: 252 | T12: 3370 | U12: 58 | V12: 1 | W12: 5.3 | X12: 119.4 | Y12: 112.7 | Z12: 6.8 | AA12: 13 | AB12: 1.16 | AC12: 12.4 | AD12: 8.7 | AE12: 28.4 | AF12: 18.7 | AG12: 10.7 | AH12: 58.4 | AI12: 63 | AJ12: 26.5 | AK12: 99.25 | AL12: 16.1 | AM12: 5215
A13: Zach LaVine | B13: SAC | C13: 1724 | D13: 622 | E13: 1221 | F13: 51.1 | G13: 533 | H13: 44.6 | I13: 237 | J13: 289 | K13: 82.5 | L13: 22 | M13: 296 | N13: 318 | O13: 311 | P13: 207 | Q13: 59 | R13: 15 | S13: 118 | T13: 2568 | U13: 6 | V13: 0 | W13: -0.9 | X13: 115.4 | Y13: 116.8 | Z13: -1.4 | AA13: 17.8 | AB13: 1.49 | AC13: 16.7 | AD13: 0.9 | AE13: 10.7 | AF13: 5.9 | AG13: 11.2 | AH13: 60.9 | AI13: 63.9 | AJ13: 25.1 | AK13: 101.28 | AL13: 11.5 | AM13: 5493
... A570: Jalen McDaniels | B570: WAS | C570: 0 | D570: 0 | E570: 0 | F570: 0 | G570: 0 | H570: 0 | I570: 0 | J570: 0 | K570: 0 | L570: 0 | M570: 0 | N570: 0 | O570: 1 | P570: 0 | Q570: 1 | R570: 0 | S570: 0 | T570: 4 | U570: 0 | V570: 0 | W570: -0.3 | X570: 81.3 | Y570: 77.8 | Z570: 3.5 | AA570: 25 | AB570: 0 | AC570: 100 | AD570: 0 | AE570: 0 | AF570: 0 | AG570: 0 | AH570: 0 | AI570: 0 | AJ570: 0 | AK570: 111.25 | AL570: 11.4 | AM570: 16

Sheet Dictionnaire des données
A1: Dictionnaire des données
A2: Player | B2: Nom du joueur
A3: Team | B3: Équipe du joueur (code à 3 lettres)
A4: Age | B4: Âge du joueur
A5: GP | B5: Nombre de matchs joués (Games Played)
A6: W | B6: Nombre de victoires de l'équipe lors des matchs joués
A7: L | B7: Nombre de défaites
A8: Min | B8: Minutes moyennes jouées par match
A9: PTS | B9: Points marqués en moyenne par match
A10: FGM | B10: Tirs réussis par match (Field Goals Made)
A11: FGA | B11: Tirs tentés par match (Field Goals Attempted)
A12: FG% | B12: Pourcentage de réussite aux tirs
A13: 0.625 | B13: Minutes jouées après 15:00 de jeu
A14: 3PA | B14: Tirs à 3 points tentés par match
A15: 3P% | B15: Pourcentage de réussite à 3 points
A16: FTM | B16: Lancers francs réussis (Free Throws Made)
A17: FTA | B17: Lancers francs tentés
A18: FT% | B18: Pourcentage de réussite aux lancers francs
A19: OREB | B19: Rebonds offensifs
A20: DREB | B20: Rebonds défensifs
A21: REB | B21: Rebonds totaux
A22: AST | B22: Passes décisives (Assists)
A23: TOV | B23: Balles perdues (Turnovers)
A24: STL | B24: Interceptions (Steals)
A25: BLK | B25: Contres (Blocks)
... A29: TD3 | B29: Triple-doubles (≥10 dans trois catégories principales)
A30: ="+ / -" -> + / - | B30: Plus-Minus (écart de score lorsque le joueur est sur le terrain)
A31: OFFRTG | B31: Offensive Rating (points marqués par 100 possessions)
A32: DEFRTG | B32: Defensive Rating (points encaissés par 100 possessions)
A33: NETRTG | B33: Net Rating = OFFRTG - DEFRTG
A34: AST% | B34: Pourcentage d'assists – implication dans les passes décisives
A35: AST/TO | B35: Ratio passes / pertes de balle
A36: AST RATIO | B36: Ratio d’assists pour 100 possessions
A37: OREB% | B37: Pourcentage de rebonds offensifs parmi ceux disponibles
A38: DREB% | B38: Idem en défensif
A39: REB% | B39: Pourcentage de rebonds totaux parmi ceux disponibles
A40: TO RATIO | B40: Turnover Ratio – pertes de balle par 100 possessions
A41: EFG% | B41: Effective Field Goal % (pondère les 3 points)
A42: TS% | B42: True Shooting % (inclut FG et FT dans l'efficacité)
... A46: POSS | B46: Nombre total de possessions jouées
